Workbook

Sheet Base de données Mono
E1: Talons de référence - ELECTRICITE | H1: Talons de référence - GAZ
A2: Chargé d'exploitation | B2: Branche | C2: Site | D2: Code site | E2: Saison de chauffe | F2: Mi-saison | G2: Saison de climatisation | H2: Saison de chauffe | I2: Mi-saison | J2: Saison de climatisation | K2: Horaire Ouv S | L2: Horaire Ferm S | M2: Horaire Ouv D | N2: Horaire Ferm D | O2: Commentaires BO | P2: Commentaires EM | Q2: Contact site
A3: JG | B3: Monoprix | C3: ABBEVILLE | D3: MO0386 | E3: 35 | F3: 35 | G3: 35 | K3: =INDEX([1]Monoprix!$F:$F,MATCH(D3,[1]Monoprix!$C:$C,0)) -> 0.1875 | L3: =INDEX([1]Monoprix!$G:$G,MATCH(D3,[1]Monoprix!$C:$C,0)) -> 0.79166667 | M3: =INDEX([1]Monoprix!$H:$H,MATCH(D3,[1]Monoprix!$C:$C,0)) -> 0.25 | N3: =INDEX([1]Monoprix!$I:$I,MATCH(D3,[1]Monoprix!$C:$C,0)) -> 0.5 | Q3: 0386dir@monoprix.fr
A4: JG | B4: SES8 | C4: AIX SEXTIUS | D4: MO0108 | E4: 70 | F4: 60 | G4: 85 | K4: =INDEX([1]Monoprix!$F:$F,MATCH(D4,[1]Monoprix!$C:$C,0)) -> 0.1875 | L4: =INDEX([1]Monoprix!$G:$G,MATCH(D4,[1]Monoprix!$C:$C,0)) -> 0.83333333 | M4: =INDEX([1]Monoprix!$H:$H,MATCH(D4,[1]Monoprix!$C:$C,0)) -> 0.25 | N4: =INDEX([1]Monoprix!$I:$I,MATCH(D4,[1]Monoprix!$C:$C,0)) -> 0.79166667 | Q4: 0108dir@monoprix.fr
A5: AD | B5: Fin CPE | C5: ALES | D5: MO2701 | E5: 30 | F5: 40 | G5: 40 | K5: =INDEX([1]Monoprix!$F:$F,MATCH(D5,[1]Monoprix!$C:$C,0)) -> 0.20833333 | L5: =INDEX([1]Monoprix!$G:$G,MATCH(D5,[1]Monoprix!$C:$C,0)) -> 0.79166667 | M5: =INDEX([1]Monoprix!$H:$H,MATCH(D5,[1]Monoprix!$C:$C,0)) -> 0.29166667 | N5: =INDEX([1]Monoprix!$I:$I,MATCH(D5,[1]Monoprix!$C:$C,0)) -> 0.54166667 | Q5: -
A6: AD | B6: SES8 | C6: ALESIA ALI | D6: MO0320 | E6: 45 | F6: 55 | G6: 65 | K6: =INDEX([1]Monoprix!$F:$F,MATCH(D6,[1]Monoprix!$C:$C,0)) -> 0.20833333 | L6: =INDEX([1]Monoprix!$G:$G,MATCH(D6,[1]Monoprix!$C:$C,0)) -> 0.83333333 | M6: =INDEX([1]Monoprix!$H:$H,MATCH(D6,[1]Monoprix!$C:$C,0)) -> 0.25 | N6: =INDEX([1]Monoprix!$I:$I,MATCH(D6,[1]Monoprix!$C:$C,0)) -> 0.54166667 | Q6: 0320dir@monoprix.fr
A7: AD | B7: SES8 | C7: ANGERS LES HALLES | D7: MO0039 | E7: 60 | F7: 60 | G7: 65 | K7: =INDEX([1]Monoprix!$F:$F,MATCH(D7,[1]Monoprix!$C:$C,0)) -> 0.20833333 | L7: =INDEX([1]Monoprix!$G:$G,MATCH(D7,[1]Monoprix!$C:$C,0)) -> 0.875 | M7: =INDEX([1]Monoprix!$H:$H,MATCH(D7,[1]Monoprix!$C:$C,0)) -> - | N7: =INDEX([1]Monoprix!$I:$I,MATCH(D7,[1]Monoprix!$C:$C,0)) -> - | Q7: 0039dir@monoprix.fr
A8: JG | B8: SES8 | C8: ANNECY COURRIER | D8: MO0332 | E8: 110 | F8: 110 | G8: 130 | K8: =INDEX([1]Monoprix!$F:$F,MATCH(D8,[1]Monoprix!$C:$C,0)) -> 0.20833333 | L8: =INDEX([1]Monoprix!$G:$G,MATCH(D8,[1]Monoprix!$C:$C,0)) -> 0.83333333 | M8: =INDEX([1]Monoprix!$H:$H,MATCH(D8,[1]Monoprix!$C:$C,0)) -> - | N8: =INDEX([1]Monoprix!$I:$I,MATCH(D8,[1]Monoprix!$C:$C,0)) -> - | Q8: 0332dir@monoprix.fr
A9: JG | B9: Monoprix | C9: ANNECY MG | D9: MO2814 | E9: 40 | F9: 45 | G9: 50 | K9: =INDEX([1]Monoprix!$F:$F,MATCH(D9,[1]Monoprix!$C:$C,0)) -> 0.20833333 | L9: =INDEX([1]Monoprix!$G:$G,MATCH(D9,[1]Monoprix!$C:$C,0)) -> 0.83333333 | M9: =INDEX([1]Monoprix!$H:$H,MATCH(D9,[1]Monoprix!$C:$C,0)) -> - | N9: =INDEX([1]Monoprix!$I:$I,MATCH(D9,[1]Monoprix!$C:$C,0)) -> - | Q9: 2814dir@monoprix.fr
A10: JG | B10: SES8 | C10: ARCUEIL | D10: MO0030 | E10: 80 | F10: 80 | G10: 105 | K10: =INDEX([1]Monoprix!$F:$F,MATCH(D10,[1]Monoprix!$C:$C,0)) -> 0.1875 | L10: =INDEX([1]Monoprix!$G:$G,MATCH(D10,[1]Monoprix!$C:$C,0)) -> 0.83333333 | M10: =INDEX([1]Monoprix!$H:$H,MATCH(D10,[1]Monoprix!$C:$C,0)) -> 0.24305556 | N10: =INDEX([1]Monoprix!$I:$I,MATCH(D10,[1]Monoprix!$C:$C,0)) -> 0.54166667 | Q10: 0030dir@monoprix.fr
A11: JG | B11: Monoprix | C11: ARRAS | D11: MO0427 | E11: 40 | F11: 40 | G11: 45 | K11: =INDEX([1]Monoprix!$F:$F,MATCH(D11,[1]Monoprix!$C:$C,0)) -> 0.1875 | L11: =INDEX([1]Monoprix!$G:$G,MATCH(D11,[1]Monoprix!$C:$C,0)) -> 0.83333333 | M11: =INDEX([1]Monoprix!$H:$H,MATCH(D11,[1]Monoprix!$C:$C,0)) -> 0.24305556 | N11: =INDEX([1]Monoprix!$I:$I,MATCH(D11,[1]Monoprix!$C:$C,0)) -> 0.54166667 | Q11: 0427dir@monoprix.fr
A12: AD | B12: Monoprix | C12: ASNIERES BOURGUIGNON | D12: MO1238 | E12: 55 | F12: 55 | G12: 60 | K12: =INDEX([1]Monoprix!$F:$F,MATCH(D12,[1]Monoprix!$C:$C,0)) -> 0.1875 | L12: =INDEX([1]Monoprix!$G:$G,MATCH(D12,[1]Monoprix!$C:$C,0)) -> 0.85416667 | M12: =INDEX([1]Monoprix!$H:$H,MATCH(D12,[1]Monoprix!$C:$C,0)) -> 0.25 | N12: =INDEX([1]Monoprix!$I:$I,MATCH(D12,[1]Monoprix!$C:$C,0)) -> 0.54166667 | Q12: 1238dir@monoprix.fr
A13: AD | B13: SES8 | C13: ASNIERES MARCHE | D13: MO0210 | E13: 45 | F13: 45 | G13: 50 | K13: =INDEX([1]Monoprix!$F:$F,MATCH(D13,[1]Monoprix!$C:$C,0)) -> 0.20833333 | L13: =INDEX([1]Monoprix!$G:$G,MATCH(D13,[1]Monoprix!$C:$C,0)) -> 0.83333333 | M13: =INDEX([1]Monoprix!$H:$H,MATCH(D13,[1]Monoprix!$C:$C,0)) -> 0.25 | N13: =INDEX([1]Monoprix!$I:$I,MATCH(D13,[1]Monoprix!$C:$C,0)) -> 0.79166667 | Q13: 0210dir@monoprix.fr
A14: AD | B14: Monoprix | C14: AURAY | D14: MO0026 | E14: 20 | F14: 25 | G14: 30 | K14: =INDEX([1]Monoprix!$F:$F,MATCH(D14,[1]Monoprix!$C:$C,0)) -> 0.20833333 | L14: =INDEX([1]Monoprix!$G:$G,MATCH(D14,[1]Monoprix!$C:$C,0)) -> 0.83333333 | M14: =INDEX([1]Monoprix!$H:$H,MATCH(D14,[1]Monoprix!$C:$C,0)) -> - | N14: =INDEX([1]Monoprix!$I:$I,MATCH(D14,[1]Monoprix!$C:$C,0)) -> - | Q14: 0026dir@monoprix.fr
... A34: AD | B34: SES8 | C34: CHAVILLE | D34: MO0162 | E34: 75 | F34: 80 | G34: 80 | K34: =INDEX([1]Monoprix!$F:$F,MATCH(D34,[1]Monoprix!$C:$C,0)) -> 0.25 | L34: =INDEX([1]Monoprix!$G:$G,MATCH(D34,[1]Monoprix!$C:$C,0)) -> 0.89583333 | M34: =INDEX([1]Monoprix!$H:$H,MATCH(D34,[1]Monoprix!$C:$C,0)) -> 0.29166667 | N34: =INDEX([1]Monoprix!$I:$I,MATCH(D34,[1]Monoprix!$C:$C,0)) -> 0.80208333 | Q34: 0162dir@monoprix.fr
A35: AD | B35: Fin CPE | C35: CLERMONT FERRAND | D35: MO2401 | E35: 10 | F35: 10 | G35: 5 | L35: 5 | M35: 20 | N35: Fermé | Q35: 2401dir@monoprix.fr
A36: AD | B36: SES8 | C36: CNIT LA DEFENSE | D36: MO2323 | E36: 50 | F36: 50 | G36: 50 | K36: =INDEX([1]Monoprix!$F:$F,MATCH(D36,[1]Monoprix!$C:$C,0)) -> 0.25 | L36: =INDEX([1]Monoprix!$G:$G,MATCH(D36,[1]Monoprix!$C:$C,0)) -> 0.875 | M36: =INDEX([1]Monoprix!$H:$H,MATCH(D36,[1]Monoprix!$C:$C,0)) -> 0.33333333 | N36: =INDEX([1]Monoprix!$I:$I,MATCH(D36,[1]Monoprix!$C:$C,0)) -> 0.83333333 | Q36: 2323dir@monoprix.fr
A37: JG | B37: Monoprix | C37: COLMAR | D37: MO0095 | E37: 80 | F37: 75 | G37: 80 | K37: =INDEX([1]Monoprix!$F:$F,MATCH(D37,[1]Monoprix!$C:$C,0)) -> 0.24305556 | L37: =INDEX([1]Monoprix!$G:$G,MATCH(D37,[1]Monoprix!$C:$C,0)) -> 0.83333333 | M37: =INDEX([1]Monoprix!$H:$H,MATCH(D37,[1]Monoprix!$C:$C,0)) -> - | N37: =INDEX([1]Monoprix!$I:$I,MATCH(D37,[1]Monoprix!$C:$C,0)) -> - | Q37: 0095dir@monoprix.fr
A38: AD | B38: SES8 | C38: COLOMBES | D38: MO0296 | E38: 75 | F38: 75 | G38: 80 | K38: =INDEX([1]Monoprix!$F:$F,MATCH(D38,[1]Monoprix!$C:$C,0)) -> 0.24305556 | L38: =INDEX([1]Monoprix!$G:$G,MATCH(D38,[1]Monoprix!$C:$C,0)) -> 0.89583333 | M38: =INDEX([1]Monoprix!$H:$H,MATCH(D38,[1]Monoprix!$C:$C,0)) -> 0.27083333 | N38: =INDEX([1]Monoprix!$I:$I,MATCH(D38,[1]Monoprix!$C:$C,0)) -> 0.55902778 | Q38: 0296dir@monoprix.fr
A39: AD | B39: SES8 | C39: COMMERCE | D39: MO0304 | E39: 75 | F39: 80 | G39: 95 | K39: =INDEX([1]Monoprix!$F:$F,MATCH(D39,[1]Monoprix!$C:$C,0)) -> 0.20833333 | L39: =INDEX([1]Monoprix!$G:$G,MATCH(D39,[1]Monoprix!$C:$C,0)) -> 0.89583333 | M39: =INDEX([1]Monoprix!$H:$H,MATCH(D39,[1]Monoprix!$C:$C,0)) -> 0.27083333 | N39: =INDEX([1]Monoprix!$I:$I,MATCH(D39,[1]Monoprix!$C:$C,0)) -> 0.55902778 | Q39: 0304dir@monoprix.fr
A40: AD | B40: SES8 | C40: COURCELLES | D40: MO1265 | E40: 45 | F40: 45 | G40: 50 | H40: 15 | I40: 15 | K40: =INDEX([1]Monoprix!$F:$F,MATCH(D40,[1]Monoprix!$C:$C,0)) -> 0.25 | L40: =INDEX([1]Monoprix!$G:$G,MATCH(D40,[1]Monoprix!$C:$C,0)) -> 0.86458333 | M40: =INDEX([1]Monoprix!$H:$H,MATCH(D40,[1]Monoprix!$C:$C,0)) -> - | N40: =INDEX([1]Monoprix!$I:$I,MATCH(D40,[1]Monoprix!$C:$C,0)) -> - | Q40: 1265dir@monoprix.fr
A41: JG | B41: Monoprix | C41: CREPY | D41: MO0100 | E41: 55 | F41: 50 | G41: 60 | K41: =INDEX([1]Monoprix!$F:$F,MATCH(D41,[1]Monoprix!$C:$C,0)) -> 0.25 | L41: =INDEX([1]Monoprix!$G:$G,MATCH(D41,[1]Monoprix!$C:$C,0)) -> 0.85416667 | M41: =INDEX([1]Monoprix!$H:$H,MATCH(D41,[1]Monoprix!$C:$C,0)) -> 0.27083333 | N41: =INDEX([1]Monoprix!$I:$I,MATCH(D41,[1]Monoprix!$C:$C,0)) -> 0.5625 | Q41: -
A42: JG | B42: SES8 | C42: CROIX ROUSSE | D42: MO0106 | E42: 80 | F42: 80 | G42: 105 | H42: 0 | I42: 0 | K42: =INDEX([1]Monoprix!$F:$F,MATCH(D42,[1]Monoprix!$C:$C,0)) -> 0.20486111 | L42: =INDEX([1]Monoprix!$G:$G,MATCH(D42,[1]Monoprix!$C:$C,0)) -> 0.89583333 | M42: =INDEX([1]Monoprix!$H:$H,MATCH(D42,[1]Monoprix!$C:$C,0)) -> 0.29166667 | N42: =INDEX([1]Monoprix!$I:$I,MATCH(D42,[1]Monoprix!$C:$C,0)) -> 0.5625 | Q42: 0106dir@monoprix.fr
A43: JG | B43: SES8 | C43: DAUMESNIL | D43: MO0253 | E43: 15 | F43: 15 | G43: 20 | K43: =INDEX([1]Monoprix!$F:$F,MATCH(D43,[1]Monoprix!$C:$C,0)) -> 0.24305556 | L43: =INDEX([1]Monoprix!$G:$G,MATCH(D43,[1]Monoprix!$C:$C,0)) -> 0.92013889 | M43: =INDEX([1]Monoprix!$H:$H,MATCH(D43,[1]Monoprix!$C:$C,0)) -> 0.28472222 | N43: =INDEX([1]Monoprix!$I:$I,MATCH(D43,[1]Monoprix!$C:$C,0)) -> 0.54166667 | Q43: 0253dir@monoprix.fr
A44: JG | B44: SES8 | C44: DIJON | D44: MO2804 | E44: 65 | F44: 55 | G44: 75 | K44: =INDEX([1]Monoprix!$F:$F,MATCH(D44,[1]Monoprix!$C:$C,0)) -> 0.24305556 | L44: =INDEX([1]Monoprix!$G:$G,MATCH(D44,[1]Monoprix!$C:$C,0)) -> 0.875 | M44: =INDEX([1]Monoprix!$H:$H,MATCH(D44,[1]Monoprix!$C:$C,0)) -> 0.3125 | N44: =INDEX([1]Monoprix!$I:$I,MATCH(D44,[1]Monoprix!$C:$C,0)) -> 0.54166667 | Q44: 2804dir@monoprix.fr
A45: JG | B45: Monoprix | C45: DRANCY | D45: MO1106 | E45: 45 | F45: 55 | G45: 55 | K45: =INDEX([1]Monoprix!$F:$F,MATCH(D45,[1]Monoprix!$C:$C,0)) -> 0.25 | L45: =INDEX([1]Monoprix!$G:$G,MATCH(D45,[1]Monoprix!$C:$C,0)) -> 0.86458333 | M45: =INDEX([1]Monoprix!$H:$H,MATCH(D45,[1]Monoprix!$C:$C,0)) -> 0.33333333 | N45: =INDEX([1]Monoprix!$I:$I,MATCH(D45,[1]Monoprix!$C:$C,0)) -> 0.55555556 | Q45: 1106dir@monoprix.fr
A46: JG | B46: Monoprix | C46: DUNKERQUE | D46: MO0416 | E46: 40 | F46: 85 | G46: 45 | K46: =INDEX([1]Monoprix!$F:$F,MATCH(D46,[1]Monoprix!$C:$C,0)) -> 0.23611111 | L46: =INDEX([1]Monoprix!$G:$G,MATCH(D46,[1]Monoprix!$C:$C,0)) -> 0.875 | M46: =INDEX([1]Monoprix!$H:$H,MATCH(D46,[1]Monoprix!$C:$C,0)) -> 0.3125 | N46: =INDEX([1]Monoprix!$I:$I,MATCH(D46,[1]Monoprix!$C:$C,0)) -> 0.55208333 | Q46: 0416dir@monoprix.fr
A47: JG | B47: Monoprix | C47: EPINAL | D47: MO2914 | E47: 35 | F47: 35 | G47: 40 | H47: 10 | I47: 0 | K47: =INDEX([1]Monoprix!$F:$F,MATCH(D47,[1]Monoprix!$C:$C,0)) -> 0.25 | L47: =INDEX([1]Monoprix!$G:$G,MATCH(D47,[1]Monoprix!$C:$C,0)) -> 0.82291667 | M47: =INDEX([1]Monoprix!$H:$H,MATCH(D47,[1]Monoprix!$C:$C,0)) -> 0.32291667 | N47: =INDEX([1]Monoprix!$I:$I,MATCH(D47,[1]Monoprix!$C:$C,0)) -> 0.53125 | Q47: -
A48: JG | B48: Monoprix | C48: FONTAINEBLEAU | D48: MO2147 | E48: 30 | F48: 35 | G48: 35 | K48: =INDEX([1]Monoprix!$F:$F,MATCH(D48,[1]Monoprix!$C:$C,0)) -> 0.25 | L48: =INDEX([1]Monoprix!$G:$G,MATCH(D48,[1]Monoprix!$C:$C,0)) -> 0.82291667 | M48: =INDEX([1]Monoprix!$H:$H,MATCH(D48,[1]Monoprix!$C:$C,0)) -> 0.3125 | N48: =INDEX([1]Monoprix!$I:$I,MATCH(D48,[1]Monoprix!$C:$C,0)) -> 0.55208333 | Q48: 2147dir@monoprix.fr
A49: AD | B49: Monoprix | C49: FONTENAY LE COMTE | D49: MO2261 | E49: 15 | F49: 15 | G49: 20 | K49: =INDEX([1]Monoprix!$F:$F,MATCH(D49,[1]Monoprix!$C:$C,0)) -> 0.29166667 | L49: =INDEX([1]Monoprix!$G:$G,MATCH(D49,[1]Monoprix!$C:$C,0)) -> 0.8125 | M49: =INDEX([1]Monoprix!$H:$H,MATCH(D49,[1]Monoprix!$C:$C,0)) -> 0.3125 | N49: =INDEX([1]Monoprix!$I:$I,MATCH(D49,[1]Monoprix!$C:$C,0)) -> 0.53125 | Q49: 2261dir@monoprix.fr
A50: JG | B50: SES8 | C50: FONTENAY SOUS BOIS | D50: MO1134 | E50: 55 | F50: 55 | G50: 70 | K50: =INDEX([1]Monoprix!$F:$F,MATCH(D50,[1]Monoprix!$C:$C,0)) -> 0.24305556 | L50: =INDEX([1]Monoprix!$G:$G,MATCH(D50,[1]Monoprix!$C:$C,0)) -> 0.89583333 | M50: =INDEX([1]Monoprix!$H:$H,MATCH(D50,[1]Monoprix!$C:$C,0)) -> 0.27083333 | N50: =INDEX([1]Monoprix!$I:$I,MATCH(D50,[1]Monoprix!$C:$C,0)) -> 0.5625 | Q50: 1134dir@monoprix.fr
A51: JG | B51: Fin CPE | C51: CAGNY | D51: MO0131 | E51: 35 | F51: 35 | G51: 35 | K51: 0.20833333 | L51: 0.83333333 | M51: 0.20833333 | N51: 0.58333333 | O51: Introuvable sur la new BD horaires GY | Q51: -
A52: JG | B52: SES8 | C52: GRASSE | D52: MO0055 | E52: 50 | F52: 55 | G52: 65 | K52: 0.20833333 | L52: 0.83333333 | M52: - | N52: - | O52: Introuvable sur la new BD horaires GY | Q52: 0055dir@monoprix.fr
A53: JG | B53: SES8 | C53: GRENOBLE CASERNE | D53: MO2317 | E53: 40 | F53: 40 | G53: 45 | K53: =INDEX([1]Monoprix!$F:$F,MATCH(D53,[1]Monoprix!$C:$C,0)) -> 0.22222222 | L53: =INDEX([1]Monoprix!$G:$G,MATCH(D53,[1]Monoprix!$C:$C,0)) -> 0.89583333 | M53: =INDEX([1]Monoprix!$H:$H,MATCH(D53,[1]Monoprix!$C:$C,0)) -> 0.3125 | N53: =INDEX([1]Monoprix!$I:$I,MATCH(D53,[1]Monoprix!$C:$C,0)) -> 0.55208333 | Q53: 2317dir@monoprix.fr
A54: JG | B54: Monoprix | C54: GRENOBLE VALLIER | D54: MO2834 | E54: 25 | F54: 25 | G54: 30 | K54: =INDEX([1]Monoprix!$F:$F,MATCH(D54,[1]Monoprix!$C:$C,0)) -> 0.24305556 | L54: =INDEX([1]Monoprix!$G:$G,MATCH(D54,[1]Monoprix!$C:$C,0)) -> 0.91666667 | M54: =INDEX([1]Monoprix!$H:$H,MATCH(D54,[1]Monoprix!$C:$C,0)) -> 0.24305556 | N54: =INDEX([1]Monoprix!$I:$I,MATCH(D54,[1]Monoprix!$C:$C,0)) -> 0.5625 | Q54: 2834dir@monoprix.fr
A55: JG | B55: Monoprix | C55: GUERET | D55: MO0199 | E55: 25 | F55: 25 | G55: 30 | K55: =INDEX([1]Monoprix!$F:$F,MATCH(D55,[1]Monoprix!$C:$C,0)) -> 0.27083333 | L55: =INDEX([1]Monoprix!$G:$G,MATCH(D55,[1]Monoprix!$C:$C,0)) -> 0.84375 | M55: =INDEX([1]Monoprix!$H:$H,MATCH(D55,[1]Monoprix!$C:$C,0)) -> 0.34375 | N55: =INDEX([1]Monoprix!$I:$I,MATCH(D55,[1]Monoprix!$C:$C,0)) -> 0.54166667 | Q55: 0199dir@monoprix.fr
A56: AD | B56: Monoprix | C56: HERBLAY | D56: MO1254 | E56: 30 | F56: 35 | G56: 35 | H56: 0 | I56: 0 | K56: =INDEX([1]Monoprix!$F:$F,MATCH(D56,[1]Monoprix!$C:$C,0)) -> 0.25 | L56: =INDEX([1]Monoprix!$G:$G,MATCH(D56,[1]Monoprix!$C:$C,0)) -> 0.83333333 | M56: =INDEX([1]Monoprix!$H:$H,MATCH(D56,[1]Monoprix!$C:$C,0)) -> 0.25 | N56: =INDEX([1]Monoprix!$I:$I,MATCH(D56,[1]Monoprix!$C:$C,0)) -> 0.55208333 | Q56: 1254dir@monoprix.fr
A57: AD | B57: Monoprix | C57: ISSOIRE | D57: MO2415 | E57: 25 | F57: 35 | G57: 35 | K57: =INDEX([1]Monoprix!$F:$F,MATCH(D57,[1]Monoprix!$C:$C,0)) -> 0.20833333 | L57: =INDEX([1]Monoprix!$G:$G,MATCH(D57,[1]Monoprix!$C:$C,0)) -> 0.83333333 | M57: =INDEX([1]Monoprix!$H:$H,MATCH(D57,[1]Monoprix!$C:$C,0)) -> 0.3125 | N57: =INDEX([1]Monoprix!$I:$I,MATCH(D57,[1]Monoprix!$C:$C,0)) -> 0.53125 | Q57: 2415dir@monoprix.fr
A58: AD | B58: SES8 | C58: ISSY GAMBETTA | D58: MO0037 | E58: 35 | F58: 35 | G58: 40 | K58: =INDEX([1]Monoprix!$F:$F,MATCH(D58,[1]Monoprix!$C:$C,0)) -> 0.25 | L58: =INDEX([1]Monoprix!$G:$G,MATCH(D58,[1]Monoprix!$C:$C,0)) -> 0.90625 | M58: =INDEX([1]Monoprix!$H:$H,MATCH(D58,[1]Monoprix!$C:$C,0)) -> 0.32638889 | N58: =INDEX([1]Monoprix!$I:$I,MATCH(D58,[1]Monoprix!$C:$C,0)) -> 0.54166667 | Q58: 0037dir@monoprix.fr
A59: AD | B59: SES8 | C59: ISSY LES MOULINEAUX | D59: MO0456 | E59: 120 | F59: 120 | G59: 95 | K59: =INDEX([1]Monoprix!$F:$F,MATCH(D59,[1]Monoprix!$C:$C,0)) -> 0.20833333 | L59: =INDEX([1]Monoprix!$G:$G,MATCH(D59,[1]Monoprix!$C:$C,0)) -> 0.91666667 | M59: =INDEX([1]Monoprix!$H:$H,MATCH(D59,[1]Monoprix!$C:$C,0)) -> 0.20833333 | N59: =INDEX([1]Monoprix!$I:$I,MATCH(D59,[1]Monoprix!$C:$C,0)) -> 0.57291667 | Q59: 0456dir@monoprix.fr
...

Sheet Suivi des alertes Monoprix
A1: Site | B1: Code site | C1: Branche | D1: Chargé d'exploitation | E1: Energie | F1: Semaine de l'alerte | G1: Mois de l'alerte | H1: Durée de fermeture Nuit | I1: Horaire Ouv S | J1: Horaire Ferm S | K1: Horaire Ouv D | L1: Horaire Ferm D | M1: Période Talon | N1: Talon ref | O1: Début surconsommation | P1: Fin surconsommation | Q1: Talon déréglé (kW) | R1: DP Surconso | S1: Nb d'heures | T1: Nb nuits/jours concernés | U1: Impact conso (kWh) | V1: Type d'impact | W1: % Surconso | X1: Période d'alerte | Y1: Type de surconso | Z1: Catégorie | AA1: Justification | AB1: Commentaires | AC1: Commentaires RAWA
A2: =INDEX('Base de données Mono'!C:C,MATCH(B2,'Base de données Mono'!D:D,0)) -> MONTPARNASSE | B2: MO0044 | C2: =INDEX('Base de données Mono'!B:B,MATCH(B2,'Base de données Mono'!D:D,0)) -> SES8 | D2: =INDEX('Base de données Mono'!A:A,MATCH(B2,'Base de données Mono'!D:D,0)) -> AD | E2: Electricité | F2: =IF(O2="","-",IF(AND(X2="Nuit",WEEKDAY(O2,2)=7,O2<>P2),WEEKNUM(O2,2),WEEKNUM(O2,2)-1))+1 -> 13 | G2: =IF(O2="","-",MONTH(O2)) -> 3 | H2: 9.67 | I2: =INDEX('Base de données Mono'!K:K,MATCH(B2,'Base de données Mono'!D:D,0)) -> 0.23611111 | J2: =INDEX('Base de données Mono'!L:L,MATCH(B2,'Base de données Mono'!D:D,0)) -> 0.875 | K2: =INDEX('Base de données Mono'!M:M,MATCH(B2,'Base de données Mono'!D:D,0)) -> 0.25 | L2: =INDEX('Base de données Mono'!N:N,MATCH(B2,'Base de données Mono'!D:D,0)) -> 0.85416667 | M2: Hiver | N2: =IF(AND(E2="Electricité",M2="Hiver"),INDEX('Base de données Mono'!E:E,MATCH(B2,'Base de données Mono'!D:D,0)),IF(AND(E2="Electricité",M2="Mi-saison"),INDEX('Base de données Mono'!F:F,MATCH(B2,'Base de données Mono'!D:D,0)),IF(AND(E2="Electricité",M2="Eté"),INDEX('Base de données Mono'!G:G,MATCH(B2,'Base de données Mono'!D:D,0)),IF(AND(E2="Gaz",M2="Hiver"),INDEX('Base de données Mono'!J:J,MATCH(B2,'Base de données Mono'!D:D,0)),IF(AND(E2="Gaz",M2="Mi-saison"),INDEX('Base de données Mono'!#REF!,MATCH(B2,'Base de données Mono'!D:D,0)),IF(AND(E2="Gaz",M2="Eté"),INDEX('Base de données Mono'!#REF!,MATCH(B2,'Base de données Mono'!D:D,0)),"-")))))) -> 125 | O2: 45375 | P2: 45381 | Q2: 190 | R2: =IF(Q2="","",Q2-N2) -> 65 | S2: 0.5 | T2: =P2-O2 -> 6 | U2: =R2*S2*T2 -> 195 | V2: - | W2: =IFERROR(IF(E2="Gaz","-",R2/N2),"-") -> 0.52 | X2: Nuit | Y2: Impact Client | Z2: Changement de comportement | AA2: Ouverture avancée
A3: =INDEX('Base de données Mono'!C:C,MATCH(B3,'Base de données Mono'!D:D,0)) -> MONTPARNASSE | B3: MO0044 | C3: =INDEX('Base de données Mono'!B:B,MATCH(B3,'Base de données Mono'!D:D,0)) -> SES8 | D3: =INDEX('Base de données Mono'!A:A,MATCH(B3,'Base de données Mono'!D:D,0)) -> AD | E3: Electricité | F3: =IF(O3="","-",IF(AND(X3="Nuit",WEEKDAY(O3,2)=7,O3<>P3),WEEKNUM(O3,2),WEEKNUM(O3,2)-1))+1 -> 13 | G3: =IF(O3="","-",MONTH(O3)) -> 3 | H3: 9.67 | I3: =INDEX('Base de données Mono'!K:K,MATCH(B3,'Base de données Mono'!D:D,0)) -> 0.23611111 | J3: =INDEX('Base de données Mono'!L:L,MATCH(B3,'Base de données Mono'!D:D,0)) -> 0.875 | K3: =INDEX('Base de données Mono'!M:M,MATCH(B3,'Base de données Mono'!D:D,0)) -> 0.25 | L3: =INDEX('Base de données Mono'!N:N,MATCH(B3,'Base de données Mono'!D:D,0)) -> 0.85416667 | M3: Hiver | N3: =IF(AND(E3="Electricité",M3="Hiver"),INDEX('Base de données Mono'!E:E,MATCH(B3,'Base de données Mono'!D:D,0)),IF(AND(E3="Electricité",M3="Mi-saison"),INDEX('Base de données Mono'!F:F,MATCH(B3,'Base de données Mono'!D:D,0)),IF(AND(E3="Electricité",M3="Eté"),INDEX('Base de données Mono'!G:G,MATCH(B3,'Base de données Mono'!D:D,0)),IF(AND(E3="Gaz",M3="Hiver"),INDEX('Base de données Mono'!J:J,MATCH(B3,'Base de données Mono'!D:D,0)),IF(AND(E3="Gaz",M3="Mi-saison"),INDEX('Base de données Mono'!#REF!,MATCH(B3,'Base de données Mono'!D:D,0)),IF(AND(E3="Gaz",M3="Eté"),INDEX('Base de données Mono'!#REF!,MATCH(B3,'Base de données Mono'!D:D,0)),"-")))))) -> 125 | O3: 45375 | P3: 45382 | Q3: 185 | R3: =IF(Q3="","",Q3-N3) -> 60 | S3: 3 | T3: =P3-O3 -> 7 | U3: =R3*S3*T3 -> 1260 | V3: - | W3: =IFERROR(IF(E3="Gaz","-",R3/N3),"-") -> 0.48 | X3: Nuit | Y3: Impact Client | Z3: Changement de comportement | AA3: Ouverture prolongée
A4: =INDEX('Base de données Mono'!C:C,MATCH(B4,'Base de données Mono'!D:D,0)) -> MOZART | B4: MO1321 | C4: =INDEX('Base de données Mono'!B:B,MATCH(B4,'Base de données Mono'!D:D,0)) -> SES8 | D4: =INDEX('Base de données Mono'!A:A,MATCH(B4,'Base de données Mono'!D:D,0)) -> AD | E4: Electricité | F4: =IF(O4="","-",IF(AND(X4="Nuit",WEEKDAY(O4,2)=7,O4<>P4),WEEKNUM(O4,2),WEEKNUM(O4,2)-1))+1 -> 13 | G4: =IF(O4="","-",MONTH(O4)) -> 3 | H4: 9.67 | I4: =INDEX('Base de données Mono'!K:K,MATCH(B4,'Base de données Mono'!D:D,0)) -> 0.23611111 | J4: =INDEX('Base de données Mono'!L:L,MATCH(B4,'Base de données Mono'!D:D,0)) -> 0.92708333 | K4: =INDEX('Base de données Mono'!M:M,MATCH(B4,'Base de données Mono'!D:D,0)) -> 0.23611111 | L4: =INDEX('Base de données Mono'!N:N,MATCH(B4,'Base de données Mono'!D:D,0)) -> 0.54166667 | M4: Hiver | N4: =IF(AND(E4="Electricité",M4="Hiver"),INDEX('Base de données Mono'!E:E,MATCH(B4,'Base de données Mono'!D:D,0)),IF(AND(E4="Electricité",M4="Mi-saison"),INDEX('Base de données Mono'!F:F,MATCH(B4,'Base de données Mono'!D:D,0)),IF(AND(E4="Electricité",M4="Eté"),INDEX('Base de données Mono'!G:G,MATCH(B4,'Base de données Mono'!D:D,0)),IF(AND(E4="Gaz",M4="Hiver"),INDEX('Base de données Mono'!J:J,MATCH(B4,'Base de données Mono'!D:D,0)),IF(AND(E4="Gaz",M4="Mi-saison"),INDEX('Base de données Mono'!#REF!,MATCH(B4,'Base de données Mono'!D:D,0)),IF(AND(E4="Gaz",M4="Eté"),INDEX('Base de données Mono'!#REF!,MATCH(B4,'Base de données Mono'!D:D,0)),"-")))))) -> 35 | O4: 45375 | P4: 45377 | Q4: 40 | R4: =IF(Q4="","",Q4-N4) -> 5 | S4: 2 | T4: =P4-O4 -> 2 | U4: =R4*S4*T4 -> 20 | V4: - | W4: =IFERROR(IF(E4="Gaz","-",R4/N4),"-") -> 0.14285714 | X4: Nuit | Y4: Impact Client | Z4: CVC | AA4: CVC en marche forcée sur GTC
A5: =INDEX('Base de données Mono'!C:C,MATCH(B5,'Base de données Mono'!D:D,0)) -> MOZART | B5: MO1321 | C5: =INDEX('Base de données Mono'!B:B,MATCH(B5,'Base de données Mono'!D:D,0)) -> SES8 | D5: =INDEX('Base de données Mono'!A:A,MATCH(B5,'Base de données Mono'!D:D,0)) -> AD | E5: Electricité | F5: =IF(O5="","-",IF(AND(X5="Nuit",WEEKDAY(O5,2)=7,O5<>P5),WEEKNUM(O5,2),WEEKNUM(O5,2)-1))+1 -> 13 | G5: =IF(O5="","-",MONTH(O5)) -> 3 | H5: 9.67 | I5: =INDEX('Base de données Mono'!K:K,MATCH(B5,'Base de données Mono'!D:D,0)) -> 0.23611111 | J5: =INDEX('Base de données Mono'!L:L,MATCH(B5,'Base de données Mono'!D:D,0)) -> 0.92708333 | K5: =INDEX('Base de données Mono'!M:M,MATCH(B5,'Base de données Mono'!D:D,0)) -> 0.23611111 | L5: =INDEX('Base de données Mono'!N:N,MATCH(B5,'Base de données Mono'!D:D,0)) -> 0.54166667 | M5: Hiver | N5: =IF(AND(E5="Electricité",M5="Hiver"),INDEX('Base de données Mono'!E:E,MATCH(B5,'Base de données Mono'!D:D,0)),IF(AND(E5="Electricité",M5="Mi-saison"),INDEX('Base de données Mono'!F:F,MATCH(B5,'Base de données Mono'!D:D,0)),IF(AND(E5="Electricité",M5="Eté"),INDEX('Base de données Mono'!G:G,MATCH(B5,'Base de données Mono'!D:D,0)),IF(AND(E5="Gaz",M5="Hiver"),INDEX('Base de données Mono'!J:J,MATCH(B5,'Base de données Mono'!D:D,0)),IF(AND(E5="Gaz",M5="Mi-saison"),INDEX('Base de données Mono'!#REF!,MATCH(B5,'Base de données Mono'!D:D,0)),IF(AND(E5="Gaz",M5="Eté"),INDEX('Base de données Mono'!#REF!,MATCH(B5,'Base de données Mono'!D:D,0)),"-")))))) -> 35 | O5: 45377 | P5: 45379 | Q5: 45 | R5: =IF(Q5="","",Q5-N5) -> 10 | S5: 7.4 | T5: =P5-O5 -> 2 | U5: =R5*S5*T5 -> 148 | V5: - | W5: =IFERROR(IF(E5="Gaz","-",R5/N5),"-") -> 0.28571429 | X5: Nuit | Y5: Impact Client | Z5: CVC | AA5: CVC en marche forcée sur GTC
A6: =INDEX('Base de données Mono'!C:C,MATCH(B6,'Base de données Mono'!D:D,0)) -> MOZART | B6: MO1321 | C6: =INDEX('Base de données Mono'!B:B,MATCH(B6,'Base de données Mono'!D:D,0)) -> SES8 | D6: =INDEX('Base de données Mono'!A:A,MATCH(B6,'Base de données Mono'!D:D,0)) -> AD | E6: Electricité | F6: =IF(O6="","-",IF(AND(X6="Nuit",WEEKDAY(O6,2)=7,O6<>P6),WEEKNUM(O6,2),WEEKNUM(O6,2)-1))+1 -> 13 | G6: =IF(O6="","-",MONTH(O6)) -> 3 | H6: 6 | I6: =INDEX('Base de données Mono'!K:K,MATCH(B6,'Base de données Mono'!D:D,0)) -> 0.23611111 | J6: =INDEX('Base de données Mono'!L:L,MATCH(B6,'Base de données Mono'!D:D,0)) -> 0.92708333 | K6: =INDEX('Base de données Mono'!M:M,MATCH(B6,'Base de données Mono'!D:D,0)) -> 0.23611111 | L6: =INDEX('Base de données Mono'!N:N,MATCH(B6,'Base de données Mono'!D:D,0)) -> 0.54166667 | M6: Hiver | N6: =IF(AND(E6="Electricité",M6="Hiver"),INDEX('Base de données Mono'!E:E,MATCH(B6,'Base de données Mono'!D:D,0)),IF(AND(E6="Electricité",M6="Mi-saison"),INDEX('Base de données Mono'!F:F,MATCH(B6,'Base de données Mono'!D:D,0)),IF(AND(E6="Electricité",M6="Eté"),INDEX('Base de données Mono'!G:G,MATCH(B6,'Base de données Mono'!D:D,0)),IF(AND(E6="Gaz",M6="Hiver"),INDEX('Base de données Mono'!J:J,MATCH(B6,'Base de données Mono'!D:D,0)),IF(AND(E6="Gaz",M6="Mi-saison"),INDEX('Base de données Mono'!#REF!,MATCH(B6,'Base de données Mono'!D:D,0)),IF(AND(E6="Gaz",M6="Eté"),INDEX('Base de données Mono'!#REF!,MATCH(B6,'Base de données Mono'!D:D,0)),"-")))))) -> 35 | O6: 45379 | P6: 45382 | Q6: 40 | R6: =IF(Q6="","",Q6-N6) -> 5 | S6: 2 | T6: =P6-O6 -> 3 | U6: =R6*S6*T6 -> 30 | V6: - | W6: =IFERROR(IF(E6="Gaz","-",R6/N6),"-") -> 0.14285714 | X6: Nuit | Y6: Impact Client | Z6: CVC | AA6: CVC en marche forcée sur GTC
A7: =INDEX('Base de données Mono'!C:C,MATCH(B7,'Base de données Mono'!D:D,0)) -> VIENNE PYRAMIDE | B7: MO0284 | C7: =INDEX('Base de données Mono'!B:B,MATCH(B7,'Base de données Mono'!D:D,0)) -> Franchisés | D7: =INDEX('Base de données Mono'!A:A,MATCH(B7,'Base de données Mono'!D:D,0)) -> AD | E7: Electricité | F7: =IF(O7="","-",IF(AND(X7="Nuit",WEEKDAY(O7,2)=7,O7<>P7),WEEKNUM(O7,2),WEEKNUM(O7,2)-1))+1 -> 13 | G7: =IF(O7="","-",MONTH(O7)) -> 3 | H7: 6 | I7: =INDEX('Base de données Mono'!K:K,MATCH(B7,'Base de données Mono'!D:D,0)) -> 0.24305556 | J7: =INDEX('Base de données Mono'!L:L,MATCH(B7,'Base de données Mono'!D:D,0)) -> 0.83333333 | K7: =INDEX('Base de données Mono'!M:M,MATCH(B7,'Base de données Mono'!D:D,0)) -> 0.29166667 | L7: =INDEX('Base de données Mono'!N:N,MATCH(B7,'Base de données Mono'!D:D,0)) -> 0.54166667 | M7: Hiver | N7: =IF(AND(E7="Electricité",M7="Hiver"),INDEX('Base de données Mono'!E:E,MATCH(B7,'Base de données Mono'!D:D,0)),IF(AND(E7="Electricité",M7="Mi-saison"),INDEX('Base de données Mono'!F:F,MATCH(B7,'Base de données Mono'!D:D,0)),IF(AND(E7="Electricité",M7="Eté"),INDEX('Base de données Mono'!G:G,MATCH(B7,'Base de données Mono'!D:D,0)),IF(AND(E7="Gaz",M7="Hiver"),INDEX('Base de données Mono'!J:J,MATCH(B7,'Base de données Mono'!D:D,0)),IF(AND(E7="Gaz",M7="Mi-saison"),INDEX('Base de données Mono'!#REF!,MATCH(B7,'Base de données Mono'!D:D,0)),IF(AND(E7="Gaz",M7="Eté"),INDEX('Base de données Mono'!#REF!,MATCH(B7,'Base de données Mono'!D:D,0)),"-")))))) -> 45 | O7: 45375 | P7: 45380 | Q7: 50 | R7: =IF(Q7="","",Q7-N7) -> 5 | S7: 2 | T7: =P7-O7 -> 5 | U7: =R7*S7*T7 -> 50 | V7: - | W7: =IFERROR(IF(E7="Gaz","-",R7/N7),"-") -> 0.11111111 | X7: Nuit | Y7: Impact Client | Z7: CVC | AA7: CVC en marche forcée sur GTC
A8: =INDEX('Base de données Mono'!C:C,MATCH(B8,'Base de données Mono'!D:D,0)) -> VIENNE PYRAMIDE | B8: MO0284 | C8: =INDEX('Base de données Mono'!B:B,MATCH(B8,'Base de données Mono'!D:D,0)) -> Franchisés | D8: =INDEX('Base de données Mono'!A:A,MATCH(B8,'Base de données Mono'!D:D,0)) -> AD | E8: Electricité | F8: =IF(O8="","-",IF(AND(X8="Nuit",WEEKDAY(O8,2)=7,O8<>P8),WEEKNUM(O8,2),WEEKNUM(O8,2)-1))+1 -> 13 | G8: =IF(O8="","-",MONTH(O8)) -> 3 | H8: 9.67 | I8: =INDEX('Base de données Mono'!K:K,MATCH(B8,'Base de données Mono'!D:D,0)) -> 0.24305556 | J8: =INDEX('Base de données Mono'!L:L,MATCH(B8,'Base de données Mono'!D:D,0)) -> 0.83333333 | K8: =INDEX('Base de données Mono'!M:M,MATCH(B8,'Base de données Mono'!D:D,0)) -> 0.29166667 | L8: =INDEX('Base de données Mono'!N:N,MATCH(B8,'Base de données Mono'!D:D,0)) -> 0.54166667 | M8: Hiver | N8: =IF(AND(E8="Electricité",M8="Hiver"),INDEX('Base de données Mono'!E:E,MATCH(B8,'Base de données Mono'!D:D,0)),IF(AND(E8="Electricité",M8="Mi-saison"),INDEX('Base de données Mono'!F:F,MATCH(B8,'Base de données Mono'!D:D,0)),IF(AND(E8="Electricité",M8="Eté"),INDEX('Base de données Mono'!G:G,MATCH(B8,'Base de données Mono'!D:D,0)),IF(AND(E8="Gaz",M8="Hiver"),INDEX('Base de données Mono'!J:J,MATCH(B8,'Base de données Mono'!D:D,0)),IF(AND(E8="Gaz",M8="Mi-saison"),INDEX('Base de données Mono'!#REF!,MATCH(B8,'Base de données Mono'!D:D,0)),IF(AND(E8="Gaz",M8="Eté"),INDEX('Base de données Mono'!#REF!,MATCH(B8,'Base de données Mono'!D:D,0)),"-")))))) -> 45 | O8: 45379 | P8: 45380 | Q8: 70 | R8: =IF(Q8="","",Q8-N8) -> 25 | S8: 2.8 | T8: =P8-O8 -> 1 | U8: =R8*S8*T8 -> 70 | V8: - | W8: =IFERROR(IF(E8="Gaz","-",R8/N8),"-") -> 0.55555556 | X8: Nuit | Y8: Impact Client | Z8: Eclairage | AA8: éclairage en marche forcée sur GTC
A9: =INDEX('Base de données Mono'!C:C,MATCH(B9,'Base de données Mono'!D:D,0)) -> VIENNE PYRAMIDE | B9: MO0284 | C9: =INDEX('Base de données Mono'!B:B,MATCH(B9,'Base de données Mono'!D:D,0)) -> Franchisés | D9: =INDEX('Base de données Mono'!A:A,MATCH(B9,'Base de données Mono'!D:D,0)) -> AD | E9: Electricité | F9: =IF(O9="","-",IF(AND(X9="Nuit",WEEKDAY(O9,2)=7,O9<>P9),WEEKNUM(O9,2),WEEKNUM(O9,2)-1))+1 -> 13 | G9: =IF(O9="","-",MONTH(O9)) -> 3 | H9: 6 | I9: =INDEX('Base de données Mono'!K:K,MATCH(B9,'Base de données Mono'!D:D,0)) -> 0.24305556 | J9: =INDEX('Base de données Mono'!L:L,MATCH(B9,'Base de données Mono'!D:D,0)) -> 0.83333333 | K9: =INDEX('Base de données Mono'!M:M,MATCH(B9,'Base de données Mono'!D:D,0)) -> 0.29166667 | L9: =INDEX('Base de données Mono'!N:N,MATCH(B9,'Base de données Mono'!D:D,0)) -> 0.54166667 | M9: Hiver | N9: =IF(AND(E9="Electricité",M9="Hiver"),INDEX('Base de données Mono'!E:E,MATCH(B9,'Base de données Mono'!D:D,0)),IF(AND(E9="Electricité",M9="Mi-saison"),INDEX('Base de données Mono'!F:F,MATCH(B9,'Base de données Mono'!D:D,0)),IF(AND(E9="Electricité",M9="Eté"),INDEX('Base de données Mono'!G:G,MATCH(B9,'Base de données Mono'!D:D,0)),IF(AND(E9="Gaz",M9="Hiver"),INDEX('Base de données Mono'!J:J,MATCH(B9,'Base de données Mono'!D:D,0)),IF(AND(E9="Gaz",M9="Mi-saison"),INDEX('Base de données Mono'!#REF!,MATCH(B9,'Base de données Mono'!D:D,0)),IF(AND(E9="Gaz",M9="Eté"),INDEX('Base de données Mono'!#REF!,MATCH(B9,'Base de données Mono'!D:D,0)),"-")))))) -> 45 | O9: 45380 | P9: 45382 | Q9: 50 | R9: =IF(Q9="","",Q9-N9) -> 5 | S9: 2 | T9: =P9-O9 -> 2 | U9: =R9*S9*T9 -> 20 | V9: - | W9: =IFERROR(IF(E9="Gaz","-",R9/N9),"-") -> 0.11111111 | X9: Nuit | Y9: Impact Client | Z9: CVC | AA9: CVC en marche forcée sur GTC
A10: =INDEX('Base de données Mono'!C:C,MATCH(B10,'Base de données Mono'!D:D,0)) -> FONTENAY SOUS BOIS | B10: MO1134 | C10: =INDEX('Base de données Mono'!B:B,MATCH(B10,'Base de données Mono'!D:D,0)) -> SES8 | D10: =INDEX('Base de données Mono'!A:A,MATCH(B10,'Base de données Mono'!D:D,0)) -> JG | E10: Electricité | F10: =IF(O10="","-",IF(AND(X10="Nuit",WEEKDAY(O10,2)=7,O10<>P10),WEEKNUM(O10,2),WEEKNUM(O10,2)-1))+1 -> 13 | G10: =IF(O10="","-",MONTH(O10)) -> 3 | H10: 8 | I10: =INDEX('Base de données Mono'!K:K,MATCH(B10,'Base de données Mono'!D:D,0)) -> 0.24305556 | J10: =INDEX('Base de données Mono'!L:L,MATCH(B10,'Base de données Mono'!D:D,0)) -> 0.89583333 | K10: =INDEX('Base de données Mono'!M:M,MATCH(B10,'Base de données Mono'!D:D,0)) -> 0.27083333 | L10: =INDEX('Base de données Mono'!N:N,MATCH(B10,'Base de données Mono'!D:D,0)) -> 0.5625 | M10: Hiver | N10: =IF(AND(E10="Electricité",M10="Hiver"),INDEX('Base de données Mono'!E:E,MATCH(B10,'Base de données Mono'!D:D,0)),IF(AND(E10="Electricité",M10="Mi-saison"),INDEX('Base de données Mono'!F:F,MATCH(B10,'Base de données Mono'!D:D,0)),IF(AND(E10="Electricité",M10="Eté"),INDEX('Base de données Mono'!G:G,MATCH(B10,'Base de données Mono'!D:D,0)),IF(AND(E10="Gaz",M10="Hiver"),INDEX('Base de données Mono'!J:J,MATCH(B10,'Base de données Mono'!D:D,0)),IF(AND(E10="Gaz",M10="Mi-saison"),INDEX('Base de données Mono'!#REF!,MATCH(B10,'Base de données Mono'!D:D,0)),IF(AND(E10="Gaz",M10="Eté"),INDEX('Base de données Mono'!#REF!,MATCH(B10,'Base de données Mono'!D:D,0)),"-")))))) -> 55 | O10: 45375 | P10: 45382 | Q10: 65 | R10: =IF(Q10="","",Q10-N10) -> 10 | S10: 7.3 | T10: =P10-O10 -> 7 | U10: =R10*S10*T10 -> 511 | V10: - | W10: =IFERROR(IF(E10="Gaz","-",R10/N10),"-") -> 0.18181818 | X10: Nuit | Y10: Impact Client | Z10: CVC | AA10: CVC en marche forcée sur GTC
A11: =INDEX('Base de données Mono'!C:C,MATCH(B11,'Base de données Mono'!D:D,0)) -> FONTENAY SOUS BOIS | B11: MO1134 | C11: =INDEX('Base de données Mono'!B:B,MATCH(B11,'Base de données Mono'!D:D,0)) -> SES8 | D11: =INDEX('Base de données Mono'!A:A,MATCH(B11,'Base de données Mono'!D:D,0)) -> JG | E11: Electricité | F11: =IF(O11="","-",IF(AND(X11="Nuit",WEEKDAY(O11,2)=7,O11<>P11),WEEKNUM(O11,2),WEEKNUM(O11,2)-1))+1 -> 13 | G11: =IF(O11="","-",MONTH(O11)) -> 3 | H11: 8 | I11: =INDEX('Base de données Mono'!K:K,MATCH(B11,'Base de données Mono'!D:D,0)) -> 0.24305556 | J11: =INDEX('Base de données Mono'!L:L,MATCH(B11,'Base de données Mono'!D:D,0)) -> 0.89583333 | K11: =INDEX('Base de données Mono'!M:M,MATCH(B11,'Base de données Mono'!D:D,0)) -> 0.27083333 | L11: =INDEX('Base de données Mono'!N:N,MATCH(B11,'Base de données Mono'!D:D,0)) -> 0.5625 | M11: Hiver | N11: =IF(AND(E11="Electricité",M11="Hiver"),INDEX('Base de données Mono'!E:E,MATCH(B11,'Base de données Mono'!D:D,0)),IF(AND(E11="Electricité",M11="Mi-saison"),INDEX('Base de données Mono'!F:F,MATCH(B11,'Base de données Mono'!D:D,0)),IF(AND(E11="Electricité",M11="Eté"),INDEX('Base de données Mono'!G:G,MATCH(B11,'Base de données Mono'!D:D,0)),IF(AND(E11="Gaz",M11="Hiver"),INDEX('Base de données Mono'!J:J,MATCH(B11,'Base de données Mono'!D:D,0)),IF(AND(E11="Gaz",M11="Mi-saison"),INDEX('Base de données Mono'!#REF!,MATCH(B11,'Base de données Mono'!D:D,0)),IF(AND(E11="Gaz",M11="Eté"),INDEX('Base de données Mono'!#REF!,MATCH(B11,'Base de données Mono'!D:D,0)),"-")))))) -> 55 | O11: 45375 | P11: 45381 | Q11: 90 | R11: =IF(Q11="","",Q11-N11) -> 35 | S11: 1 | T11: =P11-O11 -> 6 | U11: =R11*S11*T11 -> 210 | V11: - | W11: =IFERROR(IF(E11="Gaz","-",R11/N11),"-") -> 0.63636364 | X11: Nuit | Y11: Impact Client | Z11: Changement de comportement | AA11: Ouverture avancée
A12: =INDEX('Base de données Mono'!C:C,MATCH(B12,'Base de données Mono'!D:D,0)) -> FONTENAY SOUS BOIS | B12: MO1134 | C12: =INDEX('Base de données Mono'!B:B,MATCH(B12,'Base de données Mono'!D:D,0)) -> SES8 | D12: =INDEX('Base de données Mono'!A:A,MATCH(B12,'Base de données Mono'!D:D,0)) -> JG | E12: Electricité | F12: =IF(O12="","-",IF(AND(X12="Nuit",WEEKDAY(O12,2)=7,O12<>P12),WEEKNUM(O12,2),WEEKNUM(O12,2)-1))+1 -> 13 | G12: =IF(O12="","-",MONTH(O12)) -> 3 | H12: 8 | I12: =INDEX('Base de données Mono'!K:K,MATCH(B12,'Base de données Mono'!D:D,0)) -> 0.24305556 | J12: =INDEX('Base de données Mono'!L:L,MATCH(B12,'Base de données Mono'!D:D,0)) -> 0.89583333 | K12: =INDEX('Base de données Mono'!M:M,MATCH(B12,'Base de données Mono'!D:D,0)) -> 0.27083333 | L12: =INDEX('Base de données Mono'!N:N,MATCH(B12,'Base de données Mono'!D:D,0)) -> 0.5625 | M12: Hiver | N12: =IF(AND(E12="Electricité",M12="Hiver"),INDEX('Base de données Mono'!E:E,MATCH(B12,'Base de données Mono'!D:D,0)),IF(AND(E12="Electricité",M12="Mi-saison"),INDEX('Base de données Mono'!F:F,MATCH(B12,'Base de données Mono'!D:D,0)),IF(AND(E12="Electricité",M12="Eté"),INDEX('Base de données Mono'!G:G,MATCH(B12,'Base de données Mono'!D:D,0)),IF(AND(E12="Gaz",M12="Hiver"),INDEX('Base de données Mono'!J:J,MATCH(B12,'Base de données Mono'!D:D,0)),IF(AND(E12="Gaz",M12="Mi-saison"),INDEX('Base de données Mono'!#REF!,MATCH(B12,'Base de données Mono'!D:D,0)),IF(AND(E12="Gaz",M12="Eté"),INDEX('Base de données Mono'!#REF!,MATCH(B12,'Base de données Mono'!D:D,0)),"-")))))) -> 55 | O12: 45381 | P12: 45382 | Q12: 85 | R12: =IF(Q12="","",Q12-N12) -> 30 | S12: 0.5 | T12: =P12-O12 -> 1 | U12: =R12*S12*T12 -> 15 | V12: - | W12: =IFERROR(IF(E12="Gaz","-",R12/N12),"-") -> 0.54545455 | X12: Nuit | Y12: Impact Client | Z12: Changement de comportement | AA12: Ouverture avancée
A13: =INDEX('Base de données Mono'!C:C,MATCH(B13,'Base de données Mono'!D:D,0)) -> GRASSE | B13: MO0055 | C13: =INDEX('Base de données Mono'!B:B,MATCH(B13,'Base de données Mono'!D:D,0)) -> SES8 | D13: =INDEX('Base de données Mono'!A:A,MATCH(B13,'Base de données Mono'!D:D,0)) -> JG | E13: Electricité | F13: =IF(O13="","-",IF(AND(X13="Nuit",WEEKDAY(O13,2)=7,O13<>P13),WEEKNUM(O13,2),WEEKNUM(O13,2)-1))+1 -> 13 | G13: =IF(O13="","-",MONTH(O13)) -> 3 | H13: 8 | I13: =INDEX('Base de données Mono'!K:K,MATCH(B13,'Base de données Mono'!D:D,0)) -> 0.20833333 | J13: =INDEX('Base de données Mono'!L:L,MATCH(B13,'Base de données Mono'!D:D,0)) -> 0.83333333 | K13: =INDEX('Base de données Mono'!M:M,MATCH(B13,'Base de données Mono'!D:D,0)) -> - | L13: =INDEX('Base de données Mono'!N:N,MATCH(B13,'Base de données Mono'!D:D,0)) -> - | M13: Hiver | N13: =IF(AND(E13="Electricité",M13="Hiver"),INDEX('Base de données Mono'!E:E,MATCH(B13,'Base de données Mono'!D:D,0)),IF(AND(E13="Electricité",M13="Mi-saison"),INDEX('Base de données Mono'!F:F,MATCH(B13,'Base de données Mono'!D:D,0)),IF(AND(E13="Electricité",M13="Eté"),INDEX('Base de données Mono'!G:G,MATCH(B13,'Base de données Mono'!D:D,0)),IF(AND(E13="Gaz",M13="Hiver"),INDEX('Base de données Mono'!J:J,MATCH(B13,'Base de données Mono'!D:D,0)),IF(AND(E13="Gaz",M13="Mi-saison"),INDEX('Base de données Mono'!#REF!,MATCH(B13,'Base de données Mono'!D:D,0)),IF(AND(E13="Gaz",M13="Eté"),INDEX('Base de données Mono'!#REF!,MATCH(B13,'Base de données Mono'!D:D,0)),"-")))))) -> 50 | O13: 45375 | P13: 45382 | Q13: 55 | R13: =IF(Q13="","",Q13-N13) -> 5 | S13: 9 | T13: =P13-O13 -> 7 | U13: =R13*S13*T13 -> 315 | V13: - | W13: =IFERROR(IF(E13="Gaz","-",R13/N13),"-") -> 0.1 | X13: Nuit | Y13: Impact Client | Z13: CVC | AA13: CVC en marche forcée sur GTC
... A65: =INDEX('Base de données Mono'!C:C,MATCH(B65,'Base de données Mono'!D:D,0)) -> BOULOGNE LES PASSAGES | B65: MO0303 | C65: =INDEX('Base de données Mono'!B:B,MATCH(B65,'Base de données Mono'!D:D,0)) -> SES8 | D65: =INDEX('Base de données Mono'!A:A,MATCH(B65,'Base de données Mono'!D:D,0)) -> AD | E65: Electricité | F65: =IF(O65="","-",IF(AND(X65="Nuit",WEEKDAY(O65,2)=7,O65<>P65),WEEKNUM(O65,2),WEEKNUM(O65,2)-1))+1 -> 13 | G65: =IF(O65="","-",MONTH(O65)) -> 3 | H65: 10.33 | I65: =INDEX('Base de données Mono'!K:K,MATCH(B65,'Base de données Mono'!D:D,0)) -> 0.20833333 | J65: =INDEX('Base de données Mono'!L:L,MATCH(B65,'Base de données Mono'!D:D,0)) -> 0.85416667 | K65: =INDEX('Base de données Mono'!M:M,MATCH(B65,'Base de données Mono'!D:D,0)) -> - | L65: =INDEX('Base de données Mono'!N:N,MATCH(B65,'Base de données Mono'!D:D,0)) -> - | M65: Hiver | N65: =IF(AND(E65="Electricité",M65="Hiver"),INDEX('Base de données Mono'!E:E,MATCH(B65,'Base de données Mono'!D:D,0)),IF(AND(E65="Electricité",M65="Mi-saison"),INDEX('Base de données Mono'!F:F,MATCH(B65,'Base de données Mono'!D:D,0)),IF(AND(E65="Electricité",M65="Eté"),INDEX('Base de données Mono'!G:G,MATCH(B65,'Base de données Mono'!D:D,0)),IF(AND(E65="Gaz",M65="Hiver"),INDEX('Base de données Mono'!J:J,MATCH(B65,'Base de données Mono'!D:D,0)),IF(AND(E65="Gaz",M65="Mi-saison"),INDEX('Base de données Mono'!#REF!,MATCH(B65,'Base de données Mono'!D:D,0)),IF(AND(E65="Gaz",M65="Eté"),INDEX('Base de données Mono'!#REF!,MATCH(B65,'Base de données Mono'!D:D,0)),"-")))))) -> 95 | O65: 45380 | P65: 45382 | Q65: 105 | R65: =IF(Q65="","",Q65-N65) -> 10 | S65: 8.5 | T65: =P65-O65 -> 2 | U65: =R65*S65*T65 -> 170 | V65: - | W65: =IFERROR(IF(E65="Gaz","-",R65/N65),"-") -> 0.10526316 | X65: Nuit | Y65: Impact Client | Z65: CVC | AA65: CVC en marche forcée sur GTC
A66: =INDEX('Base de données Mono'!C:C,MATCH(B66,'Base de données Mono'!D:D,0)) -> ANNECY COURRIER | B66: MO0332 | C66: =INDEX('Base de données Mono'!B:B,MATCH(B66,'Base de données Mono'!D:D,0)) -> SES8 | D66: =INDEX('Base de données Mono'!A:A,MATCH(B66,'Base de données Mono'!D:D,0)) -> JG | E66: Electricité | F66: =IF(O66="","-",IF(AND(X66="Nuit",WEEKDAY(O66,2)=7,O66<>P66),WEEKNUM(O66,2),WEEKNUM(O66,2)-1))+1 -> 13 | G66: =IF(O66="","-",MONTH(O66)) -> 3 | I66: =INDEX('Base de données Mono'!K:K,MATCH(B66,'Base de données Mono'!D:D,0)) -> 0.20833333 | J66: =INDEX('Base de données Mono'!L:L,MATCH(B66,'Base de données Mono'!D:D,0)) -> 0.83333333 | K66: =INDEX('Base de données Mono'!M:M,MATCH(B66,'Base de données Mono'!D:D,0)) -> - | L66: =INDEX('Base de données Mono'!N:N,MATCH(B66,'Base de données Mono'!D:D,0)) -> - | M66: Hiver | N66: =IF(AND(E66="Electricité",M66="Hiver"),INDEX('Base de données Mono'!E:E,MATCH(B66,'Base de données Mono'!D:D,0)),IF(AND(E66="Electricité",M66="Mi-saison"),INDEX('Base de données Mono'!F:F,MATCH(B66,'Base de données Mono'!D:D,0)),IF(AND(E66="Electricité",M66="Eté"),INDEX('Base de données Mono'!G:G,MATCH(B66,'Base de données Mono'!D:D,0)),IF(AND(E66="Gaz",M66="Hiver"),INDEX('Base de données Mono'!J:J,MATCH(B66,'Base de données Mono'!D:D,0)),IF(AND(E66="Gaz",M66="Mi-saison"),INDEX('Base de données Mono'!#REF!,MATCH(B66,'Base de données Mono'!D:D,0)),IF(AND(E66="Gaz",M66="Eté"),INDEX('Base de données Mono'!#REF!,MATCH(B66,'Base de données Mono'!D:D,0)),"-")))))) -> 110 | O66: 45375 | P66: 45378 | Q66: 150 | R66: =IF(Q66="","",Q66-N66) -> 40 | S66: 9 | T66: =P66-O66 -> 3 | U66: =R66*S66*T66 -> 1080 | V66: - | W66: =IFERROR(IF(E66="Gaz","-",R66/N66),"-") -> 0.36363636 | X66: Nuit | Y66: Impact Client | Z66: CVC | AA66: CVC en marche forcée sur GTC
A67: =INDEX('Base de données Mono'!C:C,MATCH(B67,'Base de données Mono'!D:D,0)) -> ANNECY COURRIER | B67: MO0332 | C67: =INDEX('Base de données Mono'!B:B,MATCH(B67,'Base de données Mono'!D:D,0)) -> SES8 | D67: =INDEX('Base de données Mono'!A:A,MATCH(B67,'Base de données Mono'!D:D,0)) -> JG | E67: Electricité | F67: =IF(O67="","-",IF(AND(X67="Nuit",WEEKDAY(O67,2)=7,O67<>P67),WEEKNUM(O67,2),WEEKNUM(O67,2)-1))+1 -> 13 | G67: =IF(O67="","-",MONTH(O67)) -> 3 | I67: =INDEX('Base de données Mono'!K:K,MATCH(B67,'Base de données Mono'!D:D,0)) -> 0.20833333 | J67: =INDEX('Base de données Mono'!L:L,MATCH(B67,'Base de données Mono'!D:D,0)) -> 0.83333333 | K67: =INDEX('Base de données Mono'!M:M,MATCH(B67,'Base de données Mono'!D:D,0)) -> - | L67: =INDEX('Base de données Mono'!N:N,MATCH(B67,'Base de données Mono'!D:D,0)) -> - | M67: Hiver | N67: =IF(AND(E67="Electricité",M67="Hiver"),INDEX('Base de données Mono'!E:E,MATCH(B67,'Base de données Mono'!D:D,0)),IF(AND(E67="Electricité",M67="Mi-saison"),INDEX('Base de données Mono'!F:F,MATCH(B67,'Base de données Mono'!D:D,0)),IF(AND(E67="Electricité",M67="Eté"),INDEX('Base de données Mono'!G:G,MATCH(B67,'Base de données Mono'!D:D,0)),IF(AND(E67="Gaz",M67="Hiver"),INDEX('Base de données Mono'!J:J,MATCH(B67,'Base de données Mono'!D:D,0)),IF(AND(E67="Gaz",M67="Mi-saison"),INDEX('Base de données Mono'!#REF!,MATCH(B67,'Base de données Mono'!D:D,0)),IF(AND(E67="Gaz",M67="Eté"),INDEX('Base de données Mono'!#REF!,MATCH(B67,'Base de données Mono'!D:D,0)),"-")))))) -> 110 | O67: 45378 | P67: 45379 | Q67: 170 | R67: =IF(Q67="","",Q67-N67) -> 60 | S67: 9 | T67: =P67-O67 -> 1 | U67: =R67*S67*T67 -> 540 | V67: - | W67: =IFERROR(IF(E67="Gaz","-",R67/N67),"-") -> 0.54545455 | X67: Nuit | Y67: Impact Client | Z67: CVC | AA67: CVC en marche forcée sur GTC
A68: =INDEX('Base de données Mono'!C:C,MATCH(B68,'Base de données Mono'!D:D,0)) -> ANNECY COURRIER | B68: MO0332 | C68: =INDEX('Base de données Mono'!B:B,MATCH(B68,'Base de données Mono'!D:D,0)) -> SES8 | D68: =INDEX('Base de données Mono'!A:A,MATCH(B68,'Base de données Mono'!D:D,0)) -> JG | E68: Electricité | F68: =IF(O68="","-",IF(AND(X68="Nuit",WEEKDAY(O68,2)=7,O68<>P68),WEEKNUM(O68,2),WEEKNUM(O68,2)-1))+1 -> 13 | G68: =IF(O68="","-",MONTH(O68)) -> 3 | I68: =INDEX('Base de données Mono'!K:K,MATCH(B68,'Base de données Mono'!D:D,0)) -> 0.20833333 | J68: =INDEX('Base de données Mono'!L:L,MATCH(B68,'Base de données Mono'!D:D,0)) -> 0.83333333 | K68: =INDEX('Base de données Mono'!M:M,MATCH(B68,'Base de données Mono'!D:D,0)) -> - | L68: =INDEX('Base de données Mono'!N:N,MATCH(B68,'Base de données Mono'!D:D,0)) -> - | M68: Hiver | N68: =IF(AND(E68="Electricité",M68="Hiver"),INDEX('Base de données Mono'!E:E,MATCH(B68,'Base de données Mono'!D:D,0)),IF(AND(E68="Electricité",M68="Mi-saison"),INDEX('Base de données Mono'!F:F,MATCH(B68,'Base de données Mono'!D:D,0)),IF(AND(E68="Electricité",M68="Eté"),INDEX('Base de données Mono'!G:G,MATCH(B68,'Base de données Mono'!D:D,0)),IF(AND(E68="Gaz",M68="Hiver"),INDEX('Base de données Mono'!J:J,MATCH(B68,'Base de données Mono'!D:D,0)),IF(AND(E68="Gaz",M68="Mi-saison"),INDEX('Base de données Mono'!#REF!,MATCH(B68,'Base de données Mono'!D:D,0)),IF(AND(E68="Gaz",M68="Eté"),INDEX('Base de données Mono'!#REF!,MATCH(B68,'Base de données Mono'!D:D,0)),"-")))))) -> 110 | O68: 45379 | P68: 45382 | Q68: 150 | R68: =IF(Q68="","",Q68-N68) -> 40 | S68: 9 | T68: =P68-O68 -> 3 | U68: =R68*S68*T68 -> 1080 | V68: - | W68: =IFERROR(IF(E68="Gaz","-",R68/N68),"-") -> 0.36363636 | X68: Nuit | Y68: Impact Client | Z68: CVC | AA68: CVC en marche forcée sur GTC
A69: =INDEX('Base de données Mono'!C:C,MATCH(B69,'Base de données Mono'!D:D,0)) -> MARSEILLE CANNEBIERE | B69: MO0344 | C69: =INDEX('Base de données Mono'!B:B,MATCH(B69,'Base de données Mono'!D:D,0)) -> SES8 | D69: =INDEX('Base de données Mono'!A:A,MATCH(B69,'Base de données Mono'!D:D,0)) -> JG | E69: Electricité | F69: =IF(O69="","-",IF(AND(X69="Nuit",WEEKDAY(O69,2)=7,O69<>P69),WEEKNUM(O69,2),WEEKNUM(O69,2)-1))+1 -> 13 | G69: =IF(O69="","-",MONTH(O69)) -> 3 | H69: 7.75 | I69: =INDEX('Base de données Mono'!K:K,MATCH(B69,'Base de données Mono'!D:D,0)) -> 0.14583333 | J69: =INDEX('Base de données Mono'!L:L,MATCH(B69,'Base de données Mono'!D:D,0)) -> 0.875 | K69: =INDEX('Base de données Mono'!M:M,MATCH(B69,'Base de données Mono'!D:D,0)) -> 0.28472222 | L69: =INDEX('Base de données Mono'!N:N,MATCH(B69,'Base de données Mono'!D:D,0)) -> 0.54166667 | M69: Hiver | N69: =IF(AND(E69="Electricité",M69="Hiver"),INDEX('Base de données Mono'!E:E,MATCH(B69,'Base de données Mono'!D:D,0)),IF(AND(E69="Electricité",M69="Mi-saison"),INDEX('Base de données Mono'!F:F,MATCH(B69,'Base de données Mono'!D:D,0)),IF(AND(E69="Electricité",M69="Eté"),INDEX('Base de données Mono'!G:G,MATCH(B69,'Base de données Mono'!D:D,0)),IF(AND(E69="Gaz",M69="Hiver"),INDEX('Base de données Mono'!J:J,MATCH(B69,'Base de données Mono'!D:D,0)),IF(AND(E69="Gaz",M69="Mi-saison"),INDEX('Base de données Mono'!#REF!,MATCH(B69,'Base de données Mono'!D:D,0)),IF(AND(E69="Gaz",M69="Eté"),INDEX('Base de données Mono'!#REF!,MATCH(B69,'Base de données Mono'!D:D,0)),"-")))))) -> 110 | O69: 45378 | P69: 45380 | Q69: 125 | R69: =IF(Q69="","",Q69-N69) -> 15 | S69: 6.5 | T69: =P69-O69 -> 2 | U69: =R69*S69*T69 -> 195 | V69: - | W69: =IFERROR(IF(E69="Gaz","-",R69/N69),"-") -> 0.13636364 | X69: Nuit | Y69: Impact Client | Z69: CVC | AA69: CVC en marche forcée sur GTC
A70: =INDEX('Base de données Mono'!C:C,MATCH(B70,'Base de données Mono'!D:D,0)) -> MARSEILLE CANNEBIERE | B70: MO0344 | C70: =INDEX('Base de données Mono'!B:B,MATCH(B70,'Base de données Mono'!D:D,0)) -> SES8 | D70: =INDEX('Base de données Mono'!A:A,MATCH(B70,'Base de données Mono'!D:D,0)) -> JG | E70: Electricité | F70: =IF(O70="","-",IF(AND(X70="Nuit",WEEKDAY(O70,2)=7,O70<>P70),WEEKNUM(O70,2),WEEKNUM(O70,2)-1))+1 -> 13 | G70: =IF(O70="","-",MONTH(O70)) -> 3 | H70: 10.5 | I70: =INDEX('Base de données Mono'!K:K,MATCH(B70,'Base de données Mono'!D:D,0)) -> 0.14583333 | J70: =INDEX('Base de données Mono'!L:L,MATCH(B70,'Base de données Mono'!D:D,0)) -> 0.875 | K70: =INDEX('Base de données Mono'!M:M,MATCH(B70,'Base de données Mono'!D:D,0)) -> 0.28472222 | L70: =INDEX('Base de données Mono'!N:N,MATCH(B70,'Base de données Mono'!D:D,0)) -> 0.54166667 | M70: Hiver | N70: =IF(AND(E70="Electricité",M70="Hiver"),INDEX('Base de données Mono'!E:E,MATCH(B70,'Base de données Mono'!D:D,0)),IF(AND(E70="Electricité",M70="Mi-saison"),INDEX('Base de données Mono'!F:F,MATCH(B70,'Base de données Mono'!D:D,0)),IF(AND(E70="Electricité",M70="Eté"),INDEX('Base de données Mono'!G:G,MATCH(B70,'Base de données Mono'!D:D,0)),IF(AND(E70="Gaz",M70="Hiver"),INDEX('Base de données Mono'!J:J,MATCH(B70,'Base de données Mono'!D:D,0)),IF(AND(E70="Gaz",M70="Mi-saison"),INDEX('Base de données Mono'!#REF!,MATCH(B70,'Base de données Mono'!D:D,0)),IF(AND(E70="Gaz",M70="Eté"),INDEX('Base de données Mono'!#REF!,MATCH(B70,'Base de données Mono'!D:D,0)),"-")))))) -> 110 | O70: 45381 | P70: 45382 | Q70: 120 | R70: =IF(Q70="","",Q70-N70) -> 10 | S70: 2 | T70: =P70-O70 -> 1 | U70: =R70*S70*T70 -> 20 | V70: - | W70: =IFERROR(IF(E70="Gaz","-",R70/N70),"-") -> 0.090909091 | X70: Nuit | Y70: Impact Client | Z70: CVC | AA70: CVC en marche forcée sur GTC
A71: =INDEX('Base de données Mono'!C:C,MATCH(B71,'Base de données Mono'!D:D,0)) -> OULLINS | B71: MO0426 | C71: =INDEX('Base de données Mono'!B:B,MATCH(B71,'Base de données Mono'!D:D,0)) -> SES8 | D71: =INDEX('Base de données Mono'!A:A,MATCH(B71,'Base de données Mono'!D:D,0)) -> JG | E71: Electricité | F71: =IF(O71="","-",IF(AND(X71="Nuit",WEEKDAY(O71,2)=7,O71<>P71),WEEKNUM(O71,2),WEEKNUM(O71,2)-1))+1 -> 13 | G71: =IF(O71="","-",MONTH(O71)) -> 3 | H71: 9.5 | I71: =INDEX('Base de données Mono'!K:K,MATCH(B71,'Base de données Mono'!D:D,0)) -> 0.1875 | J71: =INDEX('Base de données Mono'!L:L,MATCH(B71,'Base de données Mono'!D:D,0)) -> 0.83333333 | K71: =INDEX('Base de données Mono'!M:M,MATCH(B71,'Base de données Mono'!D:D,0)) -> 0.27083333 | L71: =INDEX('Base de données Mono'!N:N,MATCH(B71,'Base de données Mono'!D:D,0)) -> 0.8125 | M71: Hiver | N71: =IF(AND(E71="Electricité",M71="Hiver"),INDEX('Base de données Mono'!E:E,MATCH(B71,'Base de données Mono'!D:D,0)),IF(AND(E71="Electricité",M71="Mi-saison"),INDEX('Base de données Mono'!F:F,MATCH(B71,'Base de données Mono'!D:D,0)),IF(AND(E71="Electricité",M71="Eté"),INDEX('Base de données Mono'!G:G,MATCH(B71,'Base de données Mono'!D:D,0)),IF(AND(E71="Gaz",M71="Hiver"),INDEX('Base de données Mono'!J:J,MATCH(B71,'Base de données Mono'!D:D,0)),IF(AND(E71="Gaz",M71="Mi-saison"),INDEX('Base de données Mono'!#REF!,MATCH(B71,'Base de données Mono'!D:D,0)),IF(AND(E71="Gaz",M71="Eté"),INDEX('Base de données Mono'!#REF!,MATCH(B71,'Base de données Mono'!D:D,0)),"-")))))) -> 40 | O71: 45375 | P71: 45382 | Q71: 70 | R71: =IF(Q71="","",Q71-N71) -> 30 | S71: 0.3 | T71: =P71-O71 -> 7 | U71: =R71*S71*T71 -> 63 | V71: - | W71: =IFERROR(IF(E71="Gaz","-",R71/N71),"-") -> 0.75 | X71: Nuit | Y71: Impact Client | Z71: Changement de comportement | AA71: Ouverture prolongée
A72: =INDEX('Base de données Mono'!C:C,MATCH(B72,'Base de données Mono'!D:D,0)) -> OULLINS | B72: MO0426 | C72: =INDEX('Base de données Mono'!B:B,MATCH(B72,'Base de données Mono'!D:D,0)) -> SES8 | D72: =INDEX('Base de données Mono'!A:A,MATCH(B72,'Base de données Mono'!D:D,0)) -> JG | E72: Electricité | F72: =IF(O72="","-",IF(AND(X72="Nuit",WEEKDAY(O72,2)=7,O72<>P72),WEEKNUM(O72,2),WEEKNUM(O72,2)-1))+1 -> 13 | G72: =IF(O72="","-",MONTH(O72)) -> 3 | H72: 10.5 | I72: =INDEX('Base de données Mono'!K:K,MATCH(B72,'Base de données Mono'!D:D,0)) -> 0.1875 | J72: =INDEX('Base de données Mono'!L:L,MATCH(B72,'Base de données Mono'!D:D,0)) -> 0.83333333 | K72: =INDEX('Base de données Mono'!M:M,MATCH(B72,'Base de données Mono'!D:D,0)) -> 0.27083333 | L72: =INDEX('Base de données Mono'!N:N,MATCH(B72,'Base de données Mono'!D:D,0)) -> 0.8125 | M72: Hiver | N72: =IF(AND(E72="Electricité",M72="Hiver"),INDEX('Base de données Mono'!E:E,MATCH(B72,'Base de données Mono'!D:D,0)),IF(AND(E72="Electricité",M72="Mi-saison"),INDEX('Base de données Mono'!F:F,MATCH(B72,'Base de données Mono'!D:D,0)),IF(AND(E72="Electricité",M72="Eté"),INDEX('Base de données Mono'!G:G,MATCH(B72,'Base de données Mono'!D:D,0)),IF(AND(E72="Gaz",M72="Hiver"),INDEX('Base de données Mono'!J:J,MATCH(B72,'Base de données Mono'!D:D,0)),IF(AND(E72="Gaz",M72="Mi-saison"),INDEX('Base de données Mono'!#REF!,MATCH(B72,'Base de données Mono'!D:D,0)),IF(AND(E72="Gaz",M72="Eté"),INDEX('Base de données Mono'!#REF!,MATCH(B72,'Base de données Mono'!D:D,0)),"-")))))) -> 40 | O72: 45375 | P72: 45382 | Q72: 50 | R72: =IF(Q72="","",Q72-N72) -> 10 | S72: 8.2 | T72: =P72-O72 -> 7 | U72: =R72*S72*T72 -> 574 | V72: - | W72: =IFERROR(IF(E72="Gaz","-",R72/N72),"-") -> 0.25 | X72: Nuit | Y72: Impact Client | Z72: CVC | AA72: CVC en marche forcée sur GTC
A73: =INDEX('Base de données Mono'!C:C,MATCH(B73,'Base de données Mono'!D:D,0)) -> POITIERS | B73: MO0514 | C73: =INDEX('Base de données Mono'!B:B,MATCH(B73,'Base de données Mono'!D:D,0)) -> SES8 | D73: =INDEX('Base de données Mono'!A:A,MATCH(B73,'Base de données Mono'!D:D,0)) -> AD | E73: Electricité | F73: =IF(O73="","-",IF(AND(X73="Nuit",WEEKDAY(O73,2)=7,O73<>P73),WEEKNUM(O73,2),WEEKNUM(O73,2)-1))+1 -> 13 | G73: =IF(O73="","-",MONTH(O73)) -> 3 | H73: 10.5 | I73: =INDEX('Base de données Mono'!K:K,MATCH(B73,'Base de données Mono'!D:D,0)) -> 0.22916667 | J73: =INDEX('Base de données Mono'!L:L,MATCH(B73,'Base de données Mono'!D:D,0)) -> 0.875 | K73: =INDEX('Base de données Mono'!M:M,MATCH(B73,'Base de données Mono'!D:D,0)) -> 0.22916667 | L73: =INDEX('Base de données Mono'!N:N,MATCH(B73,'Base de données Mono'!D:D,0)) -> 0.54166667 | M73: Hiver | N73: =IF(AND(E73="Electricité",M73="Hiver"),INDEX('Base de données Mono'!E:E,MATCH(B73,'Base de données Mono'!D:D,0)),IF(AND(E73="Electricité",M73="Mi-saison"),INDEX('Base de données Mono'!F:F,MATCH(B73,'Base de données Mono'!D:D,0)),IF(AND(E73="Electricité",M73="Eté"),INDEX('Base de données Mono'!G:G,MATCH(B73,'Base de données Mono'!D:D,0)),IF(AND(E73="Gaz",M73="Hiver"),INDEX('Base de données Mono'!J:J,MATCH(B73,'Base de données Mono'!D:D,0)),IF(AND(E73="Gaz",M73="Mi-saison"),INDEX('Base de données Mono'!#REF!,MATCH(B73,'Base de données Mono'!D:D,0)),IF(AND(E73="Gaz",M73="Eté"),INDEX('Base de données Mono'!#REF!,MATCH(B73,'Base de données Mono'!D:D,0)),"-")))))) -> 80 | O73: 45375 | P73: 45382 | Q73: 90 | R73: =IF(Q73="","",Q73-N73) -> 10 | S73: 7 | T73: =P73-O73 -> 7 | U73: =R73*S73*T73 -> 490 | V73: - | W73: =IFERROR(IF(E73="Gaz","-",R73/N73),"-") -> 0.125 | X73: Nuit | Y73: Impact Client | Z73: CVC | AA73: CVC en marche forcée sur GTC
A74: =INDEX('Base de données Mono'!C:C,MATCH(B74,'Base de données Mono'!D:D,0)) -> MONTREUIL | B74: MO0522 | C74: =INDEX('Base de données Mono'!B:B,MATCH(B74,'Base de données Mono'!D:D,0)) -> SES8 | D74: =INDEX('Base de données Mono'!A:A,MATCH(B74,'Base de données Mono'!D:D,0)) -> JG | E74: Electricité | F74: =IF(O74="","-",IF(AND(X74="Nuit",WEEKDAY(O74,2)=7,O74<>P74),WEEKNUM(O74,2),WEEKNUM(O74,2)-1))+1 -> 13 | G74: =IF(O74="","-",MONTH(O74)) -> 3 | H74: 10.5 | I74: =INDEX('Base de données Mono'!K:K,MATCH(B74,'Base de données Mono'!D:D,0)) -> 0.24305556 | J74: =INDEX('Base de données Mono'!L:L,MATCH(B74,'Base de données Mono'!D:D,0)) -> 0.875 | K74: =INDEX('Base de données Mono'!M:M,MATCH(B74,'Base de données Mono'!D:D,0)) -> 0.27083333 | L74: =INDEX('Base de données Mono'!N:N,MATCH(B74,'Base de données Mono'!D:D,0)) -> 0.55902778 | M74: Hiver | N74: =IF(AND(E74="Electricité",M74="Hiver"),INDEX('Base de données Mono'!E:E,MATCH(B74,'Base de données Mono'!D:D,0)),IF(AND(E74="Electricité",M74="Mi-saison"),INDEX('Base de données Mono'!F:F,MATCH(B74,'Base de données Mono'!D:D,0)),IF(AND(E74="Electricité",M74="Eté"),INDEX('Base de données Mono'!G:G,MATCH(B74,'Base de données Mono'!D:D,0)),IF(AND(E74="Gaz",M74="Hiver"),INDEX('Base de données Mono'!J:J,MATCH(B74,'Base de données Mono'!D:D,0)),IF(AND(E74="Gaz",M74="Mi-saison"),INDEX('Base de données Mono'!#REF!,MATCH(B74,'Base de données Mono'!D:D,0)),IF(AND(E74="Gaz",M74="Eté"),INDEX('Base de données Mono'!#REF!,MATCH(B74,'Base de données Mono'!D:D,0)),"-")))))) -> 95 | O74: 45375 | P74: 45382 | Q74: 110 | R74: =IF(Q74="","",Q74-N74) -> 15 | S74: 8.8 | T74: =P74-O74 -> 7 | U74: =R74*S74*T74 -> 924 | V74: - | W74: =IFERROR(IF(E74="Gaz","-",R74/N74),"-") -> 0.15789474 | X74: Nuit | Y74: Impact Client | Z74: CVC | AA74: CVC en marche forcée sur GTC
A75: =INDEX('Base de données Mono'!C:C,MATCH(B75,'Base de données Mono'!D:D,0)) -> MONTREUIL | B75: MO0522 | C75: =INDEX('Base de données Mono'!B:B,MATCH(B75,'Base de données Mono'!D:D,0)) -> SES8 | D75: =INDEX('Base de données Mono'!A:A,MATCH(B75,'Base de données Mono'!D:D,0)) -> JG | E75: Electricité | F75: =IF(O75="","-",IF(AND(X75="Nuit",WEEKDAY(O75,2)=7,O75<>P75),WEEKNUM(O75,2),WEEKNUM(O75,2)-1))+1 -> 13 | G75: =IF(O75="","-",MONTH(O75)) -> 3 | H75: 10.5 | I75: =INDEX('Base de données Mono'!K:K,MATCH(B75,'Base de données Mono'!D:D,0)) -> 0.24305556 | J75: =INDEX('Base de données Mono'!L:L,MATCH(B75,'Base de données Mono'!D:D,0)) -> 0.875 | K75: =INDEX('Base de données Mono'!M:M,MATCH(B75,'Base de données Mono'!D:D,0)) -> 0.27083333 | L75: =INDEX('Base de données Mono'!N:N,MATCH(B75,'Base de données Mono'!D:D,0)) -> 0.55902778 | M75: Hiver | N75: =IF(AND(E75="Electricité",M75="Hiver"),INDEX('Base de données Mono'!E:E,MATCH(B75,'Base de données Mono'!D:D,0)),IF(AND(E75="Electricité",M75="Mi-saison"),INDEX('Base de données Mono'!F:F,MATCH(B75,'Base de données Mono'!D:D,0)),IF(AND(E75="Electricité",M75="Eté"),INDEX('Base de données Mono'!G:G,MATCH(B75,'Base de données Mono'!D:D,0)),IF(AND(E75="Gaz",M75="Hiver"),INDEX('Base de données Mono'!J:J,MATCH(B75,'Base de données Mono'!D:D,0)),IF(AND(E75="Gaz",M75="Mi-saison"),INDEX('Base de données Mono'!#REF!,MATCH(B75,'Base de données Mono'!D:D,0)),IF(AND(E75="Gaz",M75="Eté"),INDEX('Base de données Mono'!#REF!,MATCH(B75,'Base de données Mono'!D:D,0)),"-")))))) -> 95 | O75: 45375 | P75: 45382 | Q75: 140 | R75: =IF(Q75="","",Q75-N75) -> 45 | S75: 0.8 | T75: =P75-O75 -> 7 | U75: =R75*S75*T75 -> 252 | V75: - | W75: =IFERROR(IF(E75="Gaz","-",R75/N75),"-") -> 0.47368421 | X75: Nuit | Y75: Impact Client | Z75: Changement de comportement | AA75: Ouverture prolongée
A76: =INDEX('Base de données Mono'!C:C,MATCH(B76,'Base de données Mono'!D:D,0)) -> MONTREUIL | B76: MO0522 | C76: =INDEX('Base de données Mono'!B:B,MATCH(B76,'Base de données Mono'!D:D,0)) -> SES8 | D76: =INDEX('Base de données Mono'!A:A,MATCH(B76,'Base de données Mono'!D:D,0)) -> JG | E76: Electricité | F76: =IF(O76="","-",IF(AND(X76="Nuit",WEEKDAY(O76,2)=7,O76<>P76),WEEKNUM(O76,2),WEEKNUM(O76,2)-1))+1 -> 13 | G76: =IF(O76="","-",MONTH(O76)) -> 3 | H76: 10 | I76: =INDEX('Base de données Mono'!K:K,MATCH(B76,'Base de données Mono'!D:D,0)) -> 0.24305556 | J76: =INDEX('Base de données Mono'!L:L,MATCH(B76,'Base de données Mono'!D:D,0)) -> 0.875 | K76: =INDEX('Base de données Mono'!M:M,MATCH(B76,'Base de données Mono'!D:D,0)) -> 0.27083333 | L76: =INDEX('Base de données Mono'!N:N,MATCH(B76,'Base de données Mono'!D:D,0)) -> 0.55902778 | M76: Hiver | N76: =IF(AND(E76="Electricité",M76="Hiver"),INDEX('Base de données Mono'!E:E,MATCH(B76,'Base de données Mono'!D:D,0)),IF(AND(E76="Electricité",M76="Mi-saison"),INDEX('Base de données Mono'!F:F,MATCH(B76,'Base de données Mono'!D:D,0)),IF(AND(E76="Electricité",M76="Eté"),INDEX('Base de données Mono'!G:G,MATCH(B76,'Base de données Mono'!D:D,0)),IF(AND(E76="Gaz",M76="Hiver"),INDEX('Base de données Mono'!J:J,MATCH(B76,'Base de données Mono'!D:D,0)),IF(AND(E76="Gaz",M76="Mi-saison"),INDEX('Base de données Mono'!#REF!,MATCH(B76,'Base de données Mono'!D:D,0)),IF(AND(E76="Gaz",M76="Eté"),INDEX('Base de données Mono'!#REF!,MATCH(B76,'Base de données Mono'!D:D,0)),"-")))))) -> 95 | O76: 45375 | P76: 45382 | Q76: 110 | R76: =IF(Q76="","",Q76-N76) -> 15 | S76: 8 | T76: =P76-O76 -> 7 | U76: =R76*S76*T76 -> 840 | V76: - | W76: =IFERROR(IF(E76="Gaz","-",R76/N76),"-") -> 0.15789474 | X76: Nuit | Y76: Impact Client | Z76: CVC | AA76: CVC en marche forcée sur GTC
